<mujoco model="walker2d">
  <compiler angle="degree" inertiafromgeom="true"/>
  <default>
    <joint armature="0.01" damping=".1" limited="true"/>
    <geom conaffinity="0" condim="3" contype="1" density="1000" friction=".7 .1 .1" rgba="0.8 0.6 .4 1"/>
  </default>
  <option integrator="RK4" timestep="0.002"/>
  <worldbody>
    <light cutoff="100" diffuse="1 1 1" dir="-0 0 -1.3" directional="true" exponent="1" pos="0 0 1.3" specular=".1 .1 .1"/>
    <geom conaffinity="1" condim="3" name="floor" pos="0 0 0" rgba="0.8 0.9 0.8 1" size="100 100 40" type="plane" material="MatPlane"/>

    <body name="torso" pos="0 0 1.25">
      <camera name="track" mode="trackcom" pos="0 -3 -0.25" xyaxes="1 0 0 0 0 1"/>
      <joint armature="0" axis="1 0 0" damping="0" limited="false" name="rootx" pos="0 0 -1.25" stiffness="0" type="slide"/>
      <joint armature="0" axis="0 0 1" damping="0" limited="false" name="rootz" pos="0 0 -1.25" ref="1.25" stiffness="0" type="slide"/>
      
      <joint armature="0" axis="0 1 0" damping="0" limited="false" name="rooty" pos="0 0 0" stiffness="0" type="hinge"/>
      <geom friction="0.9" name="torso_geom" size="0.050000000000000003 0.19999999999999996" type="capsule"/>
      <body name="thigh" pos="0 0 -0.19999999999999996">
        <joint axis="0 -1 0" name="thigh_joint" pos="0 0 0" range="-150 150" type="hinge"/>
        <geom friction="0.9" pos="0 0 -0.22500000000000009" name="thigh_geom" size="0.050000000000000003 0.22500000000000003" type="capsule"/>
        <body name="leg" pos="0 0 -0.70000000000000007">
          <joint axis="0 -1 0" name="leg_joint" pos="0 0 0.25" range="-150 0" type="hinge"/>
          <geom friction="0.9" name="leg_geom" size="0.040000000000000001 0.25" type="capsule"/>
          <body name="foot" pos="0.20000000000000001 0 -0.34999999999999998">
            <joint axis="0 -1 0" name="foot_joint" pos="-0.20000000000000001 0 0.10000000000000001" range="-45 45" type="hinge"/>
            <geom friction="1.9" pos="-0.10000000000000001 0 0.10000000000000001" quat="0.70710678118654757 0 -0.70710678118654746 0" name="foot_geom" size="0.059999999999999998 0.10000000000000001" type="capsule"/>
          </body>
        </body>
      </body>
      <!-- copied and then replace thigh->thigh_left, leg->leg_left, foot->foot_right -->
      <body name="thigh_left" pos="0 0 -0.19999999999999996">
        <joint axis="0 -1 0" name="thigh_left_joint" pos="0 0 0" range="-150 150" type="hinge"/>
        <geom friction="0.9" name="thigh_left_geom" rgba=".7 .3 .6 1" size="0.050000000000000003 0.22500000000000003" pos="0 0 -0.22500000000000009" type="capsule"/>
        <body name="leg_left" pos="0 0 -0.70000000000000007">
          <joint axis="0 -1 0" name="leg_left_joint" pos="0 0 0.25" range="-150 0" type="hinge"/>
          <geom friction="0.9" name="leg_left_geom" rgba=".7 .3 .6 1" size="0.040000000000000001 0.25" type="capsule"/>
          <body name="foot_left" pos="0.20000000000000001 0 -0.34999999999999998">
            <joint axis="0 -1 0" name="foot_left_joint" pos="-0.20000000000000001 0 0.10000000000000001" range="-45 45" type="hinge"/>
            <geom friction="1.9" name="foot_left_geom" rgba=".7 .3 .6 1" size="0.059999999999999998 0.10000000000000001" pos="-0.10000000000000001 0 0.10000000000000001" type="capsule" quat="0.70710678118654757 0 -0.70710678118654746 0"/>
          </body>
        </body>
      </body>
    </body>

    <body name="ref_torso" pos="0 0 1.25">
      <camera name="ref_track" mode="trackcom" pos="0 -3 -0.25" xyaxes="1 0 0 0 0 1"/>
      <joint name="ref_rootx" type="slide" axis="1 0 0" limited="false"/>
      <joint name="ref_rootz" type="slide" axis="0 0 1" limited="false"/>
      <joint name="ref_rooty" type="hinge" axis="0 1 0" limited="false"/>
      <geom name="ref_torso_geom" type="capsule" size="0.05 0.2" rgba="1 0 0 0.3" contype="0" conaffinity="0"/>
      <body name="ref_thigh" pos="0 0 -0.2">
        <joint name="ref_thigh_joint" type="hinge" axis="0 -1 0" range="-150 150"/>
        <geom name="ref_thigh_geom" type="capsule" pos="0 0 -0.225" size="0.05 0.225" rgba="1 0 0 0.3" contype="0" conaffinity="0"/>
        <body name="ref_leg" pos="0 0 -0.7">
          <joint name="ref_leg_joint" type="hinge" axis="0 -1 0" pos="0 0 0.25" range="-150 0"/>
          <geom name="ref_leg_geom" type="capsule" size="0.04 0.25" rgba="1 0 0 0.3" contype="0" conaffinity="0"/>
          <body name="ref_foot" pos="0.2 0 -0.35">
            <joint name="ref_foot_joint" type="hinge" axis="0 -1 0" pos="-0.2 0 0.1" range="-45 45"/>
            <geom name="ref_foot_geom" type="capsule" pos="-0.1 0 0.1" quat="0.7071 0 -0.7071 0" size="0.06 0.1" rgba="1 0 0 0.3" contype="0" conaffinity="0"/>
          </body>
        </body>
      </body>

      <body name="ref_thigh_left" pos="0 0 -0.2">
        <joint name="ref_thigh_left_joint" type="hinge" axis="0 -1 0" range="-150 150"/>
        <geom name="ref_thigh_left_geom" type="capsule" pos="0 0 -0.225" size="0.05 0.225" rgba="1 0 0 0.3" contype="0" conaffinity="0"/>     
        <body name="ref_leg_left" pos="0 0 -0.7">
          <joint name="ref_leg_left_joint" type="hinge" axis="0 -1 0" pos="0 0 0.25" range="-150 0"/>
          <geom name="ref_leg_left_geom" type="capsule" size="0.04 0.25" rgba="1 0 0 0.3" contype="0" conaffinity="0"/>
          <body name="ref_foot_left" pos="0.2 0 -0.35">
            <joint name="ref_foot_left_joint" type="hinge" axis="0 -1 0" pos="-0.2 0 0.1" range="-45 45"/>
            <geom name="ref_foot_left_geom" type="capsule" pos="-0.1 0 0.1" quat="0.7071 0 -0.7071 0" size="0.06 0.1" rgba="1 0 0 0.3" contype="0" conaffinity="0"/>
          </body>
        </body>
      </body>
    </body>

  </worldbody>
  <actuator>
    <motor ctrllimited="true" ctrlrange="-1.0 1.0" gear="100" joint="thigh_joint"/>
    <motor ctrllimited="true" ctrlrange="-1.0 1.0" gear="100" joint="leg_joint"/>
    <motor ctrllimited="true" ctrlrange="-1.0 1.0" gear="100" joint="foot_joint"/>
    <motor ctrllimited="true" ctrlrange="-1.0 1.0" gear="100" joint="thigh_left_joint"/>
    <motor ctrllimited="true" ctrlrange="-1.0 1.0" gear="100" joint="leg_left_joint"/>
    <motor ctrllimited="true" ctrlrange="-1.0 1.0" gear="100" joint="foot_left_joint"/>
  </actuator>
    <asset>
        <texture type="skybox" builtin="gradient" rgb1=".4 .5 .6" rgb2="0 0 0"
            width="100" height="100"/>
        <texture builtin="flat" height="1278" mark="cross" markrgb="1 1 1" name="texgeom" random="0.01" rgb1="0.8 0.6 0.4" rgb2="0.8 0.6 0.4" type="cube" width="127"/>
        <texture builtin="checker" height="100" name="texplane" rgb1="0 0 0" rgb2="0.8 0.8 0.8" type="2d" width="100"/>
        <material name="MatPlane" reflectance="0.5" shininess="1" specular="1" texrepeat="60 60" texture="texplane"/>
        <material name="geom" texture="texgeom" texuniform="true"/>
    </asset>
</mujoco>
